2024-09-01 19:12:24,383 INFO    StreamThr :16720 [internal.py:wandb_internal():86] W&B internal server running at pid: 16720, started at: 2024-09-01 19:12:24.383217
2024-09-01 19:12:24,386 DEBUG   HandlerThread:16720 [handler.py:handle_request():144] handle_request: status
2024-09-01 19:12:24,390 INFO    WriterThread:16720 [datastore.py:open_for_write():85] open: /Users/kelseydoerksen/code/sudsaq-kelsey-research/research/kelsey/unet/wandb/run-20240901_191224-wfszv8my/run-wfszv8my.wandb
2024-09-01 19:12:24,390 DEBUG   SenderThread:16720 [sender.py:send():380] send: header
2024-09-01 19:12:24,434 DEBUG   SenderThread:16720 [sender.py:send():380] send: run
2024-09-01 19:12:24,437 INFO    SenderThread:16720 [sender.py:_maybe_setup_resume():759] checking resume status for None/U-Net Test/wfszv8my
2024-09-01 19:12:28,357 INFO    SenderThread:16720 [retry.py:__call__():172] Retry attempt failed:
Traceback (most recent call last):
  File "/Users/kelseydoerksen/opt/anaconda3/envs/aq/lib/python3.10/site-packages/urllib3/connectionpool.py", line 703, in urlopen
    httplib_response = self._make_request(
  File "/Users/kelseydoerksen/opt/anaconda3/envs/aq/lib/python3.10/site-packages/urllib3/connectionpool.py", line 386, in _make_request
    self._validate_conn(conn)
  File "/Users/kelseydoerksen/opt/anaconda3/envs/aq/lib/python3.10/site-packages/urllib3/connectionpool.py", line 1042, in _validate_conn
    conn.connect()
  File "/Users/kelseydoerksen/opt/anaconda3/envs/aq/lib/python3.10/site-packages/urllib3/connection.py", line 414, in connect
    self.sock = ssl_wrap_socket(
  File "/Users/kelseydoerksen/opt/anaconda3/envs/aq/lib/python3.10/site-packages/urllib3/util/ssl_.py", line 449, in ssl_wrap_socket
    ssl_sock = _ssl_wrap_socket_impl(
  File "/Users/kelseydoerksen/opt/anaconda3/envs/aq/lib/python3.10/site-packages/urllib3/util/ssl_.py", line 493, in _ssl_wrap_socket_impl
    return ssl_context.wrap_socket(sock, server_hostname=server_hostname)
  File "/Users/kelseydoerksen/opt/anaconda3/envs/aq/lib/python3.10/ssl.py", line 513, in wrap_socket
    return self.sslsocket_class._create(
  File "/Users/kelseydoerksen/opt/anaconda3/envs/aq/lib/python3.10/ssl.py", line 1104, in _create
    self.do_handshake()
  File "/Users/kelseydoerksen/opt/anaconda3/envs/aq/lib/python3.10/ssl.py", line 1375, in do_handshake
    self._sslobj.do_handshake()
ssl.SSLCertVerificationError: [SSL: CERTIFICATE_VERIFY_FAILED] certificate verify failed: invalid CA certificate (_ssl.c:1007)

During handling of the above exception, another exception occurred:

Traceback (most recent call last):
  File "/Users/kelseydoerksen/opt/anaconda3/envs/aq/lib/python3.10/site-packages/requests/adapters.py", line 489, in send
    resp = conn.urlopen(
  File "/Users/kelseydoerksen/opt/anaconda3/envs/aq/lib/python3.10/site-packages/urllib3/connectionpool.py", line 787, in urlopen
    retries = retries.increment(
  File "/Users/kelseydoerksen/opt/anaconda3/envs/aq/lib/python3.10/site-packages/urllib3/util/retry.py", line 592, in increment
    raise MaxRetryError(_pool, url, error or ResponseError(cause))
urllib3.exceptions.MaxRetryError: HTTPSConnectionPool(host='api.wandb.ai', port=443): Max retries exceeded with url: /graphql (Caused by SSLError(SSLCertVerificationError(1, '[SSL: CERTIFICATE_VERIFY_FAILED] certificate verify failed: invalid CA certificate (_ssl.c:1007)')))

During handling of the above exception, another exception occurred:

Traceback (most recent call last):
  File "/Users/kelseydoerksen/opt/anaconda3/envs/aq/lib/python3.10/site-packages/wandb/sdk/lib/retry.py", line 131, in __call__
    result = self._call_fn(*args, **kwargs)
  File "/Users/kelseydoerksen/opt/anaconda3/envs/aq/lib/python3.10/site-packages/wandb/sdk/internal/internal_api.py", line 366, in execute
    return self.client.execute(*args, **kwargs)  # type: ignore
  File "/Users/kelseydoerksen/opt/anaconda3/envs/aq/lib/python3.10/site-packages/wandb/vendor/gql-0.2.0/wandb_gql/client.py", line 52, in execute
    result = self._get_result(document, *args, **kwargs)
  File "/Users/kelseydoerksen/opt/anaconda3/envs/aq/lib/python3.10/site-packages/wandb/vendor/gql-0.2.0/wandb_gql/client.py", line 60, in _get_result
    return self.transport.execute(document, *args, **kwargs)
  File "/Users/kelseydoerksen/opt/anaconda3/envs/aq/lib/python3.10/site-packages/wandb/sdk/lib/gql_request.py", line 58, in execute
    request = self.session.post(self.url, **post_args)
  File "/Users/kelseydoerksen/opt/anaconda3/envs/aq/lib/python3.10/site-packages/requests/sessions.py", line 635, in post
    return self.request("POST", url, data=data, json=json, **kwargs)
  File "/Users/kelseydoerksen/opt/anaconda3/envs/aq/lib/python3.10/site-packages/requests/sessions.py", line 587, in request
    resp = self.send(prep, **send_kwargs)
  File "/Users/kelseydoerksen/opt/anaconda3/envs/aq/lib/python3.10/site-packages/requests/sessions.py", line 701, in send
    r = adapter.send(request, **kwargs)
  File "/Users/kelseydoerksen/opt/anaconda3/envs/aq/lib/python3.10/site-packages/requests/adapters.py", line 563, in send
    raise SSLError(e, request=request)
requests.exceptions.SSLError: HTTPSConnectionPool(host='api.wandb.ai', port=443): Max retries exceeded with url: /graphql (Caused by SSLError(SSLCertVerificationError(1, '[SSL: CERTIFICATE_VERIFY_FAILED] certificate verify failed: invalid CA certificate (_ssl.c:1007)')))
2024-09-01 19:12:29,447 DEBUG   HandlerThread:16720 [handler.py:handle_request():144] handle_request: keepalive
2024-09-01 19:12:34,457 DEBUG   HandlerThread:16720 [handler.py:handle_request():144] handle_request: keepalive
2024-09-01 19:12:39,469 DEBUG   HandlerThread:16720 [handler.py:handle_request():144] handle_request: keepalive
2024-09-01 19:12:41,042 DEBUG   HandlerThread:16720 [handler.py:handle_request():144] handle_request: shutdown
2024-09-01 19:12:41,043 INFO    HandlerThread:16720 [handler.py:finish():844] shutting down handler
2024-09-01 19:12:41,467 INFO    WriterThread:16720 [datastore.py:close():294] close: /Users/kelseydoerksen/code/sudsaq-kelsey-research/research/kelsey/unet/wandb/run-20240901_191224-wfszv8my/run-wfszv8my.wandb
2024-09-01 22:18:41,308 INFO    SenderThread:16720 [dir_watcher.py:__init__():211] watching files in: /Users/kelseydoerksen/code/sudsaq-kelsey-research/research/kelsey/unet/wandb/run-20240901_191224-wfszv8my/files
2024-09-01 22:18:41,308 INFO    SenderThread:16720 [sender.py:_start_run_threads():1122] run started: wfszv8my with start time 1725214344.384165
2024-09-01 22:18:41,308 INFO    SenderThread:16720 [sender.py:finish():1534] shutting down sender
2024-09-01 22:18:41,308 INFO    SenderThread:16720 [dir_watcher.py:finish():358] shutting down directory watcher
2024-09-01 22:18:42,313 INFO    SenderThread:16720 [dir_watcher.py:finish():388] scan: /Users/kelseydoerksen/code/sudsaq-kelsey-research/research/kelsey/unet/wandb/run-20240901_191224-wfszv8my/files
2024-09-01 22:18:42,313 INFO    SenderThread:16720 [dir_watcher.py:finish():402] scan save: /Users/kelseydoerksen/code/sudsaq-kelsey-research/research/kelsey/unet/wandb/run-20240901_191224-wfszv8my/files/config.yaml config.yaml
2024-09-01 22:18:42,314 INFO    SenderThread:16720 [file_pusher.py:finish():175] shutting down file pusher
2024-09-01 22:18:42,314 INFO    SenderThread:16720 [file_pusher.py:join():181] waiting for file pusher
2024-09-01 22:18:42,971 INFO    wandb-upload_0:16720 [upload_job.py:push():131] Uploaded file /Users/kelseydoerksen/code/sudsaq-kelsey-research/research/kelsey/unet/wandb/run-20240901_191224-wfszv8my/files/config.yaml
2024-09-01 22:18:43,320 INFO    SenderThread:16720 [file_stream.py:finish():595] file stream finish called
2024-09-01 22:18:43,500 INFO    SenderThread:16720 [file_stream.py:finish():599] file stream finish is done
